<?xml version="1.0"?>
<robot name="my_rover">

  <!-- Chassis -->
  <link name="base_link">
    <visual>
      <geometry><box size="0.5 0.5 0.1"/></geometry>
      <material name="Gray"><color rgba="0.5 0.5 0.5 1"/></material>
    </visual>
    <collision>
      <geometry><box size="0.5 0.5 0.1"/></geometry>
    </collision>
    <inertial>
      <mass value="10.0"/>
      <origin xyz="0 0 0" rpy="0 0 0"/>
      <inertia ixx="0.4" ixy="0.0" ixz="0.0" iyy="0.4" iyz="0.0" izz="0.2"/>
    </inertial>
  </link>

  <!-- FRONT LEFT WHEEL -->
  <link name="front_left_steering_hub">
    <visual>
      <geometry><cylinder length="0.02" radius="0.02"/></geometry>
      <material name="DarkGray"><color rgba="0.3 0.3 0.3 1"/></material>
    </visual>
    <collision>
      <geometry><cylinder length="0.02" radius="0.02"/></geometry>
    </collision>
    <inertial>
      <mass value="0.1"/>
      <origin xyz="0 0 0" rpy="0 0 0"/>
      <inertia ixx="0.001" ixy="0.0" ixz="0.0" iyy="0.001" iyz="0.0" izz="0.001"/>
    </inertial>
  </link>

  <link name="front_left_link">
    <visual>
      <geometry><cylinder length="0.05" radius="0.08"/></geometry>
      <material name="Black"><color rgba="0 0 0 1"/></material>
    </visual>
    <collision>
      <geometry><cylinder length="0.05" radius="0.08"/></geometry>
    </collision>
    <inertial>
      <mass value="1.0"/>
      <origin xyz="0 0 0" rpy="0 0 0"/>
      <inertia ixx="0.005" ixy="0.0" ixz="0.0" iyy="0.005" iyz="0.0" izz="0.005"/>
    </inertial>
  </link>

  <joint name="front_left_steering_joint" type="revolute">
    <parent link="base_link"/>
    <child link="front_left_steering_hub"/>
    <origin xyz="0.2 0.2 -0.05" rpy="0 0 0"/>
    <axis xyz="0 0 1"/>
    <limit lower="-1.57" upper="1.57" effort="10.0" velocity="2.0"/>
    <dynamics damping="0.1" friction="0.1"/>
  </joint>

  <joint name="front_left_drive_joint" type="continuous">
    <parent link="front_left_steering_hub"/>
    <child link="front_left_link"/>
    <origin xyz="0 0 0" rpy="1.57 0 0"/>
    <axis xyz="0 0 1"/>
    <limit effort="20.0" velocity="10.0"/>
    <dynamics damping="0.1" friction="0.1"/>
  </joint>

  <!-- FRONT RIGHT WHEEL -->
  <link name="front_right_steering_hub">
    <visual>
      <geometry><cylinder length="0.02" radius="0.02"/></geometry>
      <material name="DarkGray"><color rgba="0.3 0.3 0.3 1"/></material>
    </visual>
    <collision>
      <geometry><cylinder length="0.02" radius="0.02"/></geometry>
    </collision>
    <inertial>
      <mass value="0.1"/>
      <origin xyz="0 0 0" rpy="0 0 0"/>
      <inertia ixx="0.001" ixy="0.0" ixz="0.0" iyy="0.001" iyz="0.0" izz="0.001"/>
    </inertial>
  </link>

  <link name="front_right_link">
    <visual>
      <geometry><cylinder length="0.05" radius="0.08"/></geometry>
      <material name="Black"><color rgba="0 0 0 1"/></material>
    </visual>
    <collision>
      <geometry><cylinder length="0.05" radius="0.08"/></geometry>
    </collision>
    <inertial>
      <mass value="1.0"/>
      <origin xyz="0 0 0" rpy="0 0 0"/>
      <inertia ixx="0.005" ixy="0.0" ixz="0.0" iyy="0.005" iyz="0.0" izz="0.005"/>
    </inertial>
  </link>

  <joint name="front_right_steering_joint" type="revolute">
    <parent link="base_link"/>
    <child link="front_right_steering_hub"/>
    <origin xyz="0.2 -0.2 -0.05" rpy="0 0 0"/>
    <axis xyz="0 0 1"/>
    <limit lower="-1.57" upper="1.57" effort="10.0" velocity="2.0"/>
    <dynamics damping="0.1" friction="0.1"/>
  </joint>

  <joint name="front_right_drive_joint" type="continuous">
    <parent link="front_right_steering_hub"/>
    <child link="front_right_link"/>
    <origin xyz="0 0 0" rpy="1.57 0 0"/>
    <axis xyz="0 0 1"/>
    <limit effort="20.0" velocity="10.0"/>
    <dynamics damping="0.1" friction="0.1"/>
  </joint>

  <!-- REAR LEFT WHEEL -->
  <link name="rear_left_steering_hub">
    <visual>
      <geometry><cylinder length="0.02" radius="0.02"/></geometry>
      <material name="DarkGray"><color rgba="0.3 0.3 0.3 1"/></material>
    </visual>
    <collision>
      <geometry><cylinder length="0.02" radius="0.02"/></geometry>
    </collision>
    <inertial>
      <mass value="0.1"/>
      <origin xyz="0 0 0" rpy="0 0 0"/>
      <inertia ixx="0.001" ixy="0.0" ixz="0.0" iyy="0.001" iyz="0.0" izz="0.001"/>
    </inertial>
  </link>

  <link name="rear_left_link">
    <visual>
      <geometry><cylinder length="0.05" radius="0.08"/></geometry>
      <material name="Black"><color rgba="0 0 0 1"/></material>
    </visual>
    <collision>
      <geometry><cylinder length="0.05" radius="0.08"/></geometry>
    </collision>
    <inertial>
      <mass value="1.0"/>
      <origin xyz="0 0 0" rpy="0 0 0"/>
      <inertia ixx="0.005" ixy="0.0" ixz="0.0" iyy="0.005" iyz="0.0" izz="0.005"/>
    </inertial>
  </link>

  <joint name="rear_left_steering_joint" type="revolute">
    <parent link="base_link"/>
    <child link="rear_left_steering_hub"/>
    <origin xyz="-0.2 0.2 -0.05" rpy="0 0 0"/>
    <axis xyz="0 0 1"/>
    <limit lower="-1.57" upper="1.57" effort="10.0" velocity="2.0"/>
    <dynamics damping="0.1" friction="0.1"/>
  </joint>

  <joint name="rear_left_drive_joint" type="continuous">
    <parent link="rear_left_steering_hub"/>
    <child link="rear_left_link"/>
    <origin xyz="0 0 0" rpy="1.57 0 0"/>
    <axis xyz="0 0 1"/>
    <limit effort="20.0" velocity="10.0"/>
    <dynamics damping="0.1" friction="0.1"/>
  </joint>

  <!-- REAR RIGHT WHEEL -->
  <link name="rear_right_steering_hub">
    <visual>
      <geometry><cylinder length="0.02" radius="0.02"/></geometry>
      <material name="DarkGray"><color rgba="0.3 0.3 0.3 1"/></material>
    </visual>
    <collision>
      <geometry><cylinder length="0.02" radius="0.02"/></geometry>
    </collision>
    <inertial>
      <mass value="0.1"/>
      <origin xyz="0 0 0" rpy="0 0 0"/>
      <inertia ixx="0.001" ixy="0.0" ixz="0.0" iyy="0.001" iyz="0.0" izz="0.001"/>
    </inertial>
  </link>

  <link name="rear_right_link">
    <visual>
      <geometry><cylinder length="0.05" radius="0.08"/></geometry>
      <material name="Black"><color rgba="0 0 0 1"/></material>
    </visual>
    <collision>
      <geometry><cylinder length="0.05" radius="0.08"/></geometry>
    </collision>
    <inertial>
      <mass value="1.0"/>
      <origin xyz="0 0 0" rpy="0 0 0"/>
      <inertia ixx="0.005" ixy="0.0" ixz="0.0" iyy="0.005" iyz="0.0" izz="0.005"/>
    </inertial>
  </link>

  <joint name="rear_right_steering_joint" type="revolute">
    <parent link="base_link"/>
    <child link="rear_right_steering_hub"/>
    <origin xyz="-0.2 -0.2 -0.05" rpy="0 0 0"/>
    <axis xyz="0 0 1"/>
    <limit lower="-1.57" upper="1.57" effort="10.0" velocity="2.0"/>
    <dynamics damping="0.1" friction="0.1"/>
  </joint>

  <joint name="rear_right_drive_joint" type="continuous">
    <parent link="rear_right_steering_hub"/>
    <child link="rear_right_link"/>
    <origin xyz="0 0 0" rpy="1.57 0 0"/>
    <axis xyz="0 0 1"/>
    <limit effort="20.0" velocity="10.0"/>
    <dynamics damping="0.1" friction="0.1"/>
  </joint>

  <!-- GAZEBO PLUGINS -->
  
  <!-- Gazebo ROS Control Plugin -->
  <gazebo>
    <plugin name="gazebo_ros2_control" filename="libgazebo_ros2_control.so">
      <parameters>/home/saksham-22/kratos/src/week4/config/rover_controllers.yaml</parameters>
    </plugin>
  </gazebo>

  <!-- Gazebo material properties -->
  <gazebo reference="base_link">
    <material>Gazebo/Grey</material>
  </gazebo>

  <gazebo reference="front_left_link">
    <material>Gazebo/Black</material>
    <mu1>1.0</mu1>
    <mu2>1.0</mu2>
  </gazebo>

  <gazebo reference="front_right_link">
    <material>Gazebo/Black</material>
    <mu1>1.0</mu1>
    <mu2>1.0</mu2>
  </gazebo>

  <gazebo reference="rear_left_link">
    <material>Gazebo/Black</material>
    <mu1>1.0</mu1>
    <mu2>1.0</mu2>
  </gazebo>

  <gazebo reference="rear_right_link">
    <material>Gazebo/Black</material>
    <mu1>1.0</mu1>
    <mu2>1.0</mu2>
  </gazebo>

  <!-- ROS2 Control Interface -->
  <ros2_control name="rover_hardware" type="system">
    <hardware>
      <plugin>gazebo_ros2_control/GazeboSystem</plugin>
    </hardware>
    
    <!-- Steering joints -->
    <joint name="front_left_steering_joint">
      <command_interface name="position">
        <param name="min">-1.57</param>
        <param name="max">1.57</param>
      </command_interface>
      <state_interface name="position"/>
      <state_interface name="velocity"/>
    </joint>
    
    <joint name="front_right_steering_joint">
      <command_interface name="position">
        <param name="min">-1.57</param>
        <param name="max">1.57</param>
      </command_interface>
      <state_interface name="position"/>
      <state_interface name="velocity"/>
    </joint>
    
    <joint name="rear_left_steering_joint">
      <command_interface name="position">
        <param name="min">-1.57</param>
        <param name="max">1.57</param>
      </command_interface>
      <state_interface name="position"/>
      <state_interface name="velocity"/>
    </joint>
    
    <joint name="rear_right_steering_joint">
      <command_interface name="position">
        <param name="min">-1.57</param>
        <param name="max">1.57</param>
      </command_interface>
      <state_interface name="position"/>
      <state_interface name="velocity"/>
    </joint>
    
    <!-- Drive joints -->
    <joint name="front_left_drive_joint">
      <command_interface name="velocity">
        <param name="min">-10</param>
        <param name="max">10</param>
      </command_interface>
      <state_interface name="position"/>
      <state_interface name="velocity"/>
    </joint>
    
    <joint name="front_right_drive_joint">
      <command_interface name="velocity">
        <param name="min">-10</param>
        <param name="max">10</param>
      </command_interface>
      <state_interface name="position"/>
      <state_interface name="velocity"/>
    </joint>
    
    <joint name="rear_left_drive_joint">
      <command_interface name="velocity">
        <param name="min">-10</param>
        <param name="max">10</param>
      </command_interface>
      <state_interface name="position"/>
      <state_interface name="velocity"/>
    </joint>
    
    <joint name="rear_right_drive_joint">
      <command_interface name="velocity">
        <param name="min">-10</param>
        <param name="max">10</param>
      </command_interface>
      <state_interface name="position"/>
      <state_interface name="velocity"/>
    </joint>
  </ros2_control>

</robot>